Workbook

Sheet Explanation
A1: Additional land-use claims of the Land Use Scanner demo, in hectares, per province (prvnr as in geography.dms), cumulative since the base year in the sheet Years (2022).
A2: The model reads the base year and the claim years from the sheet Years. It takes the claim at ModelYear minus the claim at StartYear, linear between the claim years (0 in the base year), and adds up the provinces per landsdeel when it allocates per landsdeel.
A3: New claims: put their base year and claim years in the sheet Years and give each land-use sheet a column <scenario>_<year> for each claim year. StartYear (the year of the land-use map) may not be before the base year.
A4: The four storylines (A1 Global Economy, A2 Transatlantic Market, B1 Strong Europe, B2 Regional Communities) are quantified with the WLO 2025 (PBL):
A5: - growth: A1 and B1 (global, most population growth) follow scenario Hoog, A2 and B2 (regional) follow scenario Laag;
A6: - spatial pattern: A (market, less restrictive) follows the uncertainty exploration Uitleg (urban expansion), B (cooperation, concentration) the exploration Verdichting (densification).
A7: Residential + industrial: growth of the built-up area per COROP region in WLO (open data, 2021 to 2040 and 2050), times the factor of the exploration, without the share of holiday parks, split into residential and industrial with the shares of the exploration (sheet Parameters).
A8: Industrial land grows less in WLO 2025 than in the past (CBS land-use statistics 1996-2017: 1,343 ha per year). Recreation grew at 1,056 ha per year in the same period, so in some scenarios it now grows as much as industrial land.
A9: Recreation: holiday parks as the share of the growth of the built-up area in WLO (modelled with the Land Use Scanner, figure 4.2), plus day recreation: population growth per COROP region in WLO times the current day recreation area per inhabitant.
A10: Nature: A1 and A2 the minimum of the Nature Network Netherlands (NNN), B1 its maximum, B2 the new nature of the Nature Outlook that WLO uses; realised before 2030 and divided over the provinces as the new nature in WLO.
A11: Building lot: stays at its current area. Agriculture: takes the rest, per province, so that the claims of each province add up to 0.
A12: WLO 2025 starts in 2021; its growth from 2021 counts from the base year 2022, the year of the land-use map (CBS NBBG2022, 1 January 2022). 2030 lies linearly between the base year and 2040.
... A15: Built by Object Vision, 2026-10-22.

Sheet Years
A1: year | B1: role | C1: description
A2: 2022 | B2: base | C2: Base year: the claims in the land-use sheets are cumulative from this year (0 in this year). It is the year of the land-use map (CBS NBBG2022, 1 January 2022). WLO 2025 starts in 2021; its growth from 2021 counts from this year.
A3: 2030 | B3: claim | C3: Linear between the base year and 2040: share_2030 in the sheet Parameters.
A4: 2040 | B4: claim | C4: WLO 2025.
A5: 2050 | B5: claim | C5: WLO 2025.

Sheet COROP
A1: code | B1: name | C1: province | D1: prvnr | E1: builtup_2021 | F1: builtup_2040_Hoog | G1: builtup_2050_Hoog | H1: builtup_2040_Laag | I1: builtup_2050_Laag | J1: pop_2021 | K1: pop_2040_Hoog | L1: pop_2050_Hoog | M1: pop_2040_Laag | N1: pop_2050_Laag | O1: nature_2021 | P1: nature_2040_Hoog | Q1: nature_2040_Laag | R1: d_builtup_2040_Hoog | S1: d_builtup_2050_Hoog | T1: d_builtup_2040_Laag | U1: d_builtup_2050_Laag | V1: d_pop_2040_Hoog | W1: d_pop_2050_Hoog | X1: d_pop_2040_Laag | Y1: d_pop_2050_Laag | Z1: d_nature_2040_Hoog | AA1: d_nature_2040_Laag
A2: 1 | B2: Oost-Groningen | C2: Groningen | D2: 1 | E2: 54.3 | F2: 55.9 | G2: 56.6 | H2: 55.5 | I2: 56.7 | J2: 136 | K2: 135 | L2: 134 | M2: 127 | N2: 123 | O2: 67.7 | P2: 78.2 | Q2: 78.2 | R2: =MAX(F2-E2,0)*100 -> 160 | S2: =MAX(G2-E2,0)*100 -> 230 | T2: =MAX(H2-E2,0)*100 -> 120 | U2: =MAX(I2-E2,0)*100 -> 240 | V2: =MAX(K2-J2,0)*1000 -> 0 | W2: =MAX(L2-J2,0)*1000 -> 0 | X2: =MAX(M2-J2,0)*1000 -> 0 | Y2: =MAX(N2-J2,0)*1000 -> 0 | Z2: =MAX(P2-O2,0)*100 -> 1050 | AA2: =MAX(Q2-O2,0)*100 -> 1050
A3: 2 | B3: Delfzijl en omgeving | C3: Groningen | D3: 1 | E3: 18.5 | F3: 19.2 | G3: 19.3 | H3: 19.3 | I3: 19.8 | J3: 46 | K3: 46 | L3: 45 | M3: 44 | N3: 43 | O3: 7.4 | P3: 9.2 | Q3: 9.2 | R3: =MAX(F3-E3,0)*100 -> 70 | S3: =MAX(G3-E3,0)*100 -> 80 | T3: =MAX(H3-E3,0)*100 -> 80 | U3: =MAX(I3-E3,0)*100 -> 130 | V3: =MAX(K3-J3,0)*1000 -> 0 | W3: =MAX(L3-J3,0)*1000 -> 0 | X3: =MAX(M3-J3,0)*1000 -> 0 | Y3: =MAX(N3-J3,0)*1000 -> 0 | Z3: =MAX(P3-O3,0)*100 -> 180 | AA3: =MAX(Q3-O3,0)*100 -> 180
A4: 3 | B4: Overig Groningen | C4: Groningen | D4: 1 | E4: 106.8 | F4: 118.7 | G4: 122.4 | H4: 113.2 | I4: 115.8 | J4: 405 | K4: 474 | L4: 492 | M4: 446 | N4: 442 | O4: 119.1 | P4: 149.9 | Q4: 149.9 | R4: =MAX(F4-E4,0)*100 -> 1190 | S4: =MAX(G4-E4,0)*100 -> 1560 | T4: =MAX(H4-E4,0)*100 -> 640 | U4: =MAX(I4-E4,0)*100 -> 900 | V4: =MAX(K4-J4,0)*1000 -> 69000 | W4: =MAX(L4-J4,0)*1000 -> 87000 | X4: =MAX(M4-J4,0)*1000 -> 41000 | Y4: =MAX(N4-J4,0)*1000 -> 37000 | Z4: =MAX(P4-O4,0)*100 -> 3080 | AA4: =MAX(Q4-O4,0)*100 -> 3080
A5: 4 | B5: Noord-Friesland | C5: Friesland | D5: 2 | E5: 103 | F5: 113.1 | G5: 117.3 | H5: 111.4 | I5: 117.2 | J5: 321 | K5: 340 | L5: 345 | M5: 326 | N5: 324 | O5: 268.9 | P5: 308 | Q5: 307.9 | R5: =MAX(F5-E5,0)*100 -> 1010 | S5: =MAX(G5-E5,0)*100 -> 1430 | T5: =MAX(H5-E5,0)*100 -> 840 | U5: =MAX(I5-E5,0)*100 -> 1420 | V5: =MAX(K5-J5,0)*1000 -> 19000 | W5: =MAX(L5-J5,0)*1000 -> 24000 | X5: =MAX(M5-J5,0)*1000 -> 5000 | Y5: =MAX(N5-J5,0)*1000 -> 3000 | Z5: =MAX(P5-O5,0)*100 -> 3910 | AA5: =MAX(Q5-O5,0)*100 -> 3900
A6: 5 | B6: Zuidwest-Friesland | C6: Friesland | D6: 2 | E6: 49.5 | F6: 52.2 | G6: 55.3 | H6: 52.2 | I6: 56.4 | J6: 142 | K6: 140 | L6: 141 | M6: 132 | N6: 130 | O6: 59.1 | P6: 77 | Q6: 77 | R6: =MAX(F6-E6,0)*100 -> 270 | S6: =MAX(G6-E6,0)*100 -> 580 | T6: =MAX(H6-E6,0)*100 -> 270 | U6: =MAX(I6-E6,0)*100 -> 690 | V6: =MAX(K6-J6,0)*1000 -> 0 | W6: =MAX(L6-J6,0)*1000 -> 0 | X6: =MAX(M6-J6,0)*1000 -> 0 | Y6: =MAX(N6-J6,0)*1000 -> 0 | Z6: =MAX(P6-O6,0)*100 -> 1790 | AA6: =MAX(Q6-O6,0)*100 -> 1790
A7: 6 | B7: Zuidoost-Friesland | C7: Friesland | D7: 2 | E7: 60.9 | F7: 64.7 | G7: 66.1 | H7: 63.2 | I7: 64.6 | J7: 188 | K7: 195 | L7: 198 | M7: 183 | N7: 179 | O7: 157.6 | P7: 172.7 | Q7: 172.7 | R7: =MAX(F7-E7,0)*100 -> 380 | S7: =MAX(G7-E7,0)*100 -> 520 | T7: =MAX(H7-E7,0)*100 -> 230 | U7: =MAX(I7-E7,0)*100 -> 370 | V7: =MAX(K7-J7,0)*1000 -> 7000 | W7: =MAX(L7-J7,0)*1000 -> 10000 | X7: =MAX(M7-J7,0)*1000 -> 0 | Y7: =MAX(N7-J7,0)*1000 -> 0 | Z7: =MAX(P7-O7,0)*100 -> 1510 | AA7: =MAX(Q7-O7,0)*100 -> 1510
A8: 7 | B8: Noord-Drenthe | C8: Drenthe | D8: 3 | E8: 74.5 | F8: 79.8 | G8: 82.8 | H8: 77.5 | I8: 79.9 | J8: 193 | K8: 200 | L8: 205 | M8: 187 | N8: 185 | O8: 297.7 | P8: 338.8 | Q8: 339 | R8: =MAX(F8-E8,0)*100 -> 530 | S8: =MAX(G8-E8,0)*100 -> 830 | T8: =MAX(H8-E8,0)*100 -> 300 | U8: =MAX(I8-E8,0)*100 -> 540 | V8: =MAX(K8-J8,0)*1000 -> 7000 | W8: =MAX(L8-J8,0)*1000 -> 12000 | X8: =MAX(M8-J8,0)*1000 -> 0 | Y8: =MAX(N8-J8,0)*1000 -> 0 | Z8: =MAX(P8-O8,0)*100 -> 4110 | AA8: =MAX(Q8-O8,0)*100 -> 4130
A9: 8 | B9: Zuidoost-Drenthe | C9: Drenthe | D9: 3 | E9: 69.5 | F9: 73.2 | G9: 75.1 | H9: 72.4 | I9: 74.7 | J9: 168 | K9: 164 | L9: 160 | M9: 155 | N9: 150 | O9: 149.6 | P9: 167.2 | Q9: 167.2 | R9: =MAX(F9-E9,0)*100 -> 370 | S9: =MAX(G9-E9,0)*100 -> 560 | T9: =MAX(H9-E9,0)*100 -> 290 | U9: =MAX(I9-E9,0)*100 -> 520 | V9: =MAX(K9-J9,0)*1000 -> 0 | W9: =MAX(L9-J9,0)*1000 -> 0 | X9: =MAX(M9-J9,0)*1000 -> 0 | Y9: =MAX(N9-J9,0)*1000 -> 0 | Z9: =MAX(P9-O9,0)*100 -> 1760 | AA9: =MAX(Q9-O9,0)*100 -> 1760
A10: 9 | B10: Zuidwest-Drenthe | C10: Drenthe | D10: 3 | E10: 44.1 | F10: 50 | G10: 51.9 | H10: 48.9 | I10: 50.6 | J10: 134 | K10: 139 | L10: 140 | M10: 132 | N10: 129 | O10: 191.8 | P10: 207.8 | Q10: 207.8 | R10: =MAX(F10-E10,0)*100 -> 590 | S10: =MAX(G10-E10,0)*100 -> 780 | T10: =MAX(H10-E10,0)*100 -> 480 | U10: =MAX(I10-E10,0)*100 -> 650 | V10: =MAX(K10-J10,0)*1000 -> 5000 | W10: =MAX(L10-J10,0)*1000 -> 6000 | X10: =MAX(M10-J10,0)*1000 -> 0 | Y10: =MAX(N10-J10,0)*1000 -> 0 | Z10: =MAX(P10-O10,0)*100 -> 1600 | AA10: =MAX(Q10-O10,0)*100 -> 1600
A11: 10 | B11: Noord-Overijssel | C11: Overijssel | D11: 4 | E11: 106.8 | F11: 122.9 | G11: 136.3 | H11: 118 | I11: 125.1 | J11: 378 | K11: 425 | L11: 456 | M11: 399 | N11: 404 | O11: 253.8 | P11: 283.7 | Q11: 283.7 | R11: =MAX(F11-E11,0)*100 -> 1610 | S11: =MAX(G11-E11,0)*100 -> 2950 | T11: =MAX(H11-E11,0)*100 -> 1120 | U11: =MAX(I11-E11,0)*100 -> 1830 | V11: =MAX(K11-J11,0)*1000 -> 47000 | W11: =MAX(L11-J11,0)*1000 -> 78000 | X11: =MAX(M11-J11,0)*1000 -> 21000 | Y11: =MAX(N11-J11,0)*1000 -> 26000 | Z11: =MAX(P11-O11,0)*100 -> 2990 | AA11: =MAX(Q11-O11,0)*100 -> 2990
A12: 11 | B12: Zuidwest-Overijssel | C12: Overijssel | D12: 4 | E12: 35.8 | F12: 38 | G12: 39.3 | H12: 36.8 | I12: 37.1 | J12: 158 | K12: 171 | L12: 175 | M12: 158 | N12: 155 | O12: 52.7 | P12: 59 | Q12: 59.1 | R12: =MAX(F12-E12,0)*100 -> 220 | S12: =MAX(G12-E12,0)*100 -> 350 | T12: =MAX(H12-E12,0)*100 -> 100 | U12: =MAX(I12-E12,0)*100 -> 130 | V12: =MAX(K12-J12,0)*1000 -> 13000 | W12: =MAX(L12-J12,0)*1000 -> 17000 | X12: =MAX(M12-J12,0)*1000 -> 0 | Y12: =MAX(N12-J12,0)*1000 -> 0 | Z12: =MAX(P12-O12,0)*100 -> 630 | AA12: =MAX(Q12-O12,0)*100 -> 640
A13: 12 | B13: Twente | C13: Overijssel | D13: 4 | E13: 164.6 | F13: 174.6 | G13: 177.4 | H13: 170.8 | I13: 173.3 | J13: 632 | K13: 643 | L13: 640 | M13: 611 | N13: 591 | O13: 294.9 | P13: 334 | Q13: 334.1 | R13: =MAX(F13-E13,0)*100 -> 1000 | S13: =MAX(G13-E13,0)*100 -> 1280 | T13: =MAX(H13-E13,0)*100 -> 620 | U13: =MAX(I13-E13,0)*100 -> 870 | V13: =MAX(K13-J13,0)*1000 -> 11000 | W13: =MAX(L13-J13,0)*1000 -> 8000 | X13: =MAX(M13-J13,0)*1000 -> 0 | Y13: =MAX(N13-J13,0)*1000 -> 0 | Z13: =MAX(P13-O13,0)*100 -> 3910 | AA13: =MAX(Q13-O13,0)*100 -> 3920
... A41: 40 | B41: Flevoland | C41: Flevoland | D41: 12 | E41: 101.9 | F41: 137.7 | G41: 160.2 | H41: 117.7 | I41: 127 | J41: 429 | K41: 555 | L41: 609 | M41: 470 | N41: 475 | O41: 250.8 | P41: 270.8 | Q41: 272.3 | R41: =MAX(F41-E41,0)*100 -> 3580 | S41: =MAX(G41-E41,0)*100 -> 5830 | T41: =MAX(H41-E41,0)*100 -> 1580 | U41: =MAX(I41-E41,0)*100 -> 2510 | V41: =MAX(K41-J41,0)*1000 -> 126000 | W41: =MAX(L41-J41,0)*1000 -> 180000 | X41: =MAX(M41-J41,0)*1000 -> 41000 | Y41: =MAX(N41-J41,0)*1000 -> 46000 | Z41: =MAX(P41-O41,0)*100 -> 2000 | AA41: =MAX(Q41-O41,0)*100 -> 2150
A43: Built-up area and nature in km2, population in thousands (WLO 2025, open data cahier Regionale ontwikkelingen en ruimtegebruik). Columns d_ are growth since 2021: built-up area and nature in ha, population in persons; decline counts as 0.

Sheet Parameters
A1: Parameter | B1: Value | C1: Description
A2: share_2030 | B2: =(2030-Years!A2)/(2040-Years!A2) -> 0.44444444 | C2: Share of the growth up to 2040 that is reached in 2030: linear from the base year in the sheet Years.
A3: recreation_base_year_ha | B3: 125994.48 | C3: Current recreation area in the land-use map of the base year (CBS NBBG2022 in this demo).
A4: population_2021 | B4: =SUM(COROP!J2:J41)*1000 -> 17475000 | C4: Population in WLO 2021.
A5: day_recreation_ha_per_inhabitant | B5: =(B3-B26)/B4 -> 0.0059951445 | C5: Area for day recreation (parks, sports, allotments, day recreation sites) per inhabitant, kept constant: the current recreation area minus holiday parks.
A7: Figure 4.2 of the WLO cahier: share of the land area in 2060 (2021 for the base), percent; measured from the figure
A8: variant | B8: residential | C8: industrial | D8: holiday parks | E8: growth total | F8: factor to reference | G8: residential share of res+ind | H8: holiday park share of growth
A9: 2021 | B9: 7.34 | C9: 3.98 | D9: 0.61
A10: Hoog | B10: 9.63 | C10: 4.59 | D10: 0.76 | E10: =(B10+C10+D10)-(B$9+C$9+D$9) -> 3.05 | F10: 1 | G10: =(B10-B$9)/((B10-B$9)+(C10-C$9)) -> 0.78965517 | H10: =(D10-D$9)/E10 -> 0.049180328
A11: Hoog Verdichting | B11: 8.87 | C11: 4.59 | D11: 0.92 | E11: =(B11+C11+D11)-(B$9+C$9+D$9) -> 2.45 | F11: =E11/E10 -> 0.80327869 | G11: =(B11-B$9)/((B11-B$9)+(C11-C$9)) -> 0.71495327 | H11: =(D11-D$9)/E11 -> 0.12653061
A12: Hoog Uitleg | B12: 10.09 | C12: 4.89 | D12: 0.76 | E12: =(B12+C12+D12)-(B$9+C$9+D$9) -> 3.81 | F12: =E12/E10 -> 1.2491803 | G12: =(B12-B$9)/((B12-B$9)+(C12-C$9)) -> 0.75136612 | H12: =(D12-D$9)/E12 -> 0.039370079
A13: Laag | B13: 7.95 | C13: 4.74 | D13: 0.76 | E13: =(B13+C13+D13)-(B$9+C$9+D$9) -> 1.52 | F13: 1 | G13: =(B13-B$9)/((B13-B$9)+(C13-C$9)) -> 0.44525547 | H13: =(D13-D$9)/E13 -> 0.098684211
A14: Laag Verdichting | B14: 7.8 | C14: 4.59 | D14: 0.92 | E14: =(B14+C14+D14)-(B$9+C$9+D$9) -> 1.38 | F14: =E14/E13 -> 0.90789474 | G14: =(B14-B$9)/((B14-B$9)+(C14-C$9)) -> 0.42990654 | H14: =(D14-D$9)/E14 -> 0.22463768
A15: Laag Uitleg | B15: 7.95 | C15: 4.89 | D15: 0.76 | E15: =(B15+C15+D15)-(B$9+C$9+D$9) -> 1.67 | F15: =E15/E13 -> 1.0986842 | G15: =(B15-B$9)/((B15-B$9)+(C15-C$9)) -> 0.40131579 | H15: =(D15-D$9)/E15 -> 0.089820359
A17: Scenarios
A18: scenario | B18: WLO growth | C18: WLO exploration | D18: nature claim (ha) | E18: nature source
A19: A1 | B19: Hoog | C19: Uitleg | D19: 35000 | E19: NNN minimum: 703,000 ha realised, at least 738,000 ha in 2028 (CLO)
A20: A2 | B20: Laag | C20: Uitleg | D20: 35000 | E20: NNN minimum, as A1
A21: B1 | B21: Hoog | C21: Verdichting | D21: 71000 | E21: NNN maximum: up to 774,000 ha in 2028 (CLO)
A22: B2 | B22: Laag | C22: Verdichting | D22: =SUM(COROP!AA2:AA41) -> 94880 | E22: New nature of the Nature Outlook in WLO 2025 Laag (2021-2040), realised in 2030
A24: Base for recreation
A25: land_area_km2 | B25: =SUM(COROP!E2:E41)/((B9+C9+D9)/100) -> 34802.179 | C25: Land area: built-up area 2021 in WLO divided by its share of the land area in figure 4.2.
A26: holiday_parks_2021_ha | B26: =D9/100*B25*100 -> 21229.329 | C26: Holiday parks in 2021: their share of the land area in figure 4.2.

Sheet Province
A1: prvnr | B1: province | C1: RstIntPer | D1: A1_residential_2030 | E1: A1_residential_2040 | F1: A1_residential_2050 | G1: A1_industrial_2030 | H1: A1_industrial_2040 | I1: A1_industrial_2050 | J1: A1_recreation_2030 | K1: A1_recreation_2040 | L1: A1_recreation_2050 | M1: A1_nature_2030 | N1: A1_nature_2040 | O1: A1_nature_2050 | P1: A2_residential_2030 | Q1: A2_residential_2040 | R1: A2_residential_2050 | S1: A2_industrial_2030 | T1: A2_industrial_2040 | U1: A2_industrial_2050 | V1: A2_recreation_2030 | W1: A2_recreation_2040 | X1: A2_recreation_2050 | Y1: A2_nature_2030 | Z1: A2_nature_2040 | AA1: A2_nature_2050 | AB1: B1_residential_2030 | AC1: B1_residential_2040 | AD1: B1_residential_2050 | AE1: B1_industrial_2030 | AF1: B1_industrial_2040 | AG1: B1_industrial_2050 | AH1: B1_recreation_2030 | AI1: B1_recreation_2040 | AJ1: B1_recreation_2050 | AK1: B1_nature_2030 | AL1: B1_nature_2040 | AM1: B1_nature_2050 | AN1: B2_residential_2030 | AO1: B2_residential_2040 | AP1: B2_residential_2050 | AQ1: B2_industrial_2030 | AR1: B2_industrial_2040 | AS1: B2_industrial_2050 | AT1: B2_recreation_2030 | AU1: B2_recreation_2040 | AV1: B2_recreation_2050 | AW1: B2_nature_2030 | AX1: B2_nature_2040 | AY1: B2_nature_2050
A2: 1 | B2: Groningen | C2: 3 | D2: =E2*Parameters!$B$2 -> 569.03461 | E2: =SUMIFS(COROP!$R$2:$R$41,COROP!$D$2:$D$41,$A2)*Parameters!$F$12*(1-Parameters!$H$12)*Parameters!$G$12 -> 1280.3279 | F2: =SUMIFS(COROP!$S$2:$S$41,COROP!$D$2:$D$41,$A2)*Parameters!$F$12*(1-Parameters!$H$12)*Parameters!$G$12 -> 1686.0656 | G2: =H2*Parameters!$B$2 -> 188.29872 | H2: =SUMIFS(COROP!$R$2:$R$41,COROP!$D$2:$D$41,$A2)*Parameters!$F$12*(1-Parameters!$H$12)*(1-Parameters!$G$12) -> 423.67213 | I2: =SUMIFS(COROP!$S$2:$S$41,COROP!$D$2:$D$41,$A2)*Parameters!$F$12*(1-Parameters!$H$12)*(1-Parameters!$G$12) -> 557.93443 | J2: =K2*Parameters!$B$2 -> 214.88935 | K2: =SUMIFS(COROP!$V$2:$V$41,COROP!$D$2:$D$41,$A2)*Parameters!$B$5+SUMIFS(COROP!$R$2:$R$41,COROP!$D$2:$D$41,$A2)*Parameters!$F$12*Parameters!$H$12 -> 483.50104 | L2: =SUMIFS(COROP!$W$2:$W$41,COROP!$D$2:$D$41,$A2)*Parameters!$B$5+SUMIFS(COROP!$S$2:$S$41,COROP!$D$2:$D$41,$A2)*Parameters!$F$12*Parameters!$H$12 -> 613.54479 | M2: =Parameters!$D$19*SUMIFS(COROP!$Z$2:$Z$41,COROP!$D$2:$D$41,$A2)/SUM(COROP!$Z$2:$Z$41) -> 1595.7897 | N2: =Parameters!$D$19*SUMIFS(COROP!$Z$2:$Z$41,COROP!$D$2:$D$41,$A2)/SUM(COROP!$Z$2:$Z$41) -> 1595.7897 | O2: =Parameters!$D$19*SUMIFS(COROP!$Z$2:$Z$41,COROP!$D$2:$D$41,$A2)/SUM(COROP!$Z$2:$Z$41) -> 1595.7897 | P2: =Q2*Parameters!$B$2 -> 149.82456 | Q2: =SUMIFS(COROP!$T$2:$T$41,COROP!$D$2:$D$41,$A2)*Parameters!$F$15*(1-Parameters!$H$15)*Parameters!$G$15 -> 337.10526 | R2: =SUMIFS(COROP!$U$2:$U$41,COROP!$D$2:$D$41,$A2)*Parameters!$F$15*(1-Parameters!$H$15)*Parameters!$G$15 -> 509.67105 | S2: =T2*Parameters!$B$2 -> 223.50877 | T2: =SUMIFS(COROP!$T$2:$T$41,COROP!$D$2:$D$41,$A2)*Parameters!$F$15*(1-Parameters!$H$15)*(1-Parameters!$G$15) -> 502.89474 | U2: =SUMIFS(COROP!$U$2:$U$41,COROP!$D$2:$D$41,$A2)*Parameters!$F$15*(1-Parameters!$H$15)*(1-Parameters!$G$15) -> 760.32895 | V2: =W2*Parameters!$B$2 -> 146.08696 | W2: =SUMIFS(COROP!$X$2:$X$41,COROP!$D$2:$D$41,$A2)*Parameters!$B$5+SUMIFS(COROP!$T$2:$T$41,COROP!$D$2:$D$41,$A2)*Parameters!$F$15*Parameters!$H$15 -> 328.69566 | X2: =SUMIFS(COROP!$Y$2:$Y$41,COROP!$D$2:$D$41,$A2)*Parameters!$B$5+SUMIFS(COROP!$U$2:$U$41,COROP!$D$2:$D$41,$A2)*Parameters!$F$15*Parameters!$H$15 -> 347.14929 | Y2: =Parameters!$D$20*SUMIFS(COROP!$AA$2:$AA$41,COROP!$D$2:$D$41,$A2)/SUM(COROP!$AA$2:$AA$41) -> 1589.903 | Z2: =Parameters!$D$20*SUMIFS(COROP!$AA$2:$AA$41,COROP!$D$2:$D$41,$A2)/SUM(COROP!$AA$2:$AA$41) -> 1589.903 | AA2: =Parameters!$D$20*SUMIFS(COROP!$AA$2:$AA$41,COROP!$D$2:$D$41,$A2)/SUM(COROP!$AA$2:$AA$41) -> 1589.903 | AB2: =AC2*Parameters!$B$2 -> 316.59016 | AC2: =SUMIFS(COROP!$R$2:$R$41,COROP!$D$2:$D$41,$A2)*Parameters!$F$11*(1-Parameters!$H$11)*Parameters!$G$11 -> 712.32787 | AD2: =SUMIFS(COROP!$S$2:$S$41,COROP!$D$2:$D$41,$A2)*Parameters!$F$11*(1-Parameters!$H$11)*Parameters!$G$11 -> 938.06557 | AE2: =AF2*Parameters!$B$2 -> 126.22222 | AF2: =SUMIFS(COROP!$R$2:$R$41,COROP!$D$2:$D$41,$A2)*Parameters!$F$11*(1-Parameters!$H$11)*(1-Parameters!$G$11) -> 284 | AG2: =SUMIFS(COROP!$S$2:$S$41,COROP!$D$2:$D$41,$A2)*Parameters!$F$11*(1-Parameters!$H$11)*(1-Parameters!$G$11) -> 374 | AH2: =AI2*Parameters!$B$2 -> 247.99682 | AI2: =SUMIFS(COROP!$V$2:$V$41,COROP!$D$2:$D$41,$A2)*Parameters!$B$5+SUMIFS(COROP!$R$2:$R$41,COROP!$D$2:$D$41,$A2)*Parameters!$F$11*Parameters!$H$11 -> 557.99284 | AJ2: =SUMIFS(COROP!$W$2:$W$41,COROP!$D$2:$D$41,$A2)*Parameters!$B$5+SUMIFS(COROP!$S$2:$S$41,COROP!$D$2:$D$41,$A2)*Parameters!$F$11*Parameters!$H$11 -> 711.64315 | AK2: =Parameters!$D$21*SUMIFS(COROP!$Z$2:$Z$41,COROP!$D$2:$D$41,$A2)/SUM(COROP!$Z$2:$Z$41) -> 3237.1734 | AL2: =Parameters!$D$21*SUMIFS(COROP!$Z$2:$Z$41,COROP!$D$2:$D$41,$A2)/SUM(COROP!$Z$2:$Z$41) -> 3237.1734 | AM2: =Parameters!$D$21*SUMIFS(COROP!$Z$2:$Z$41,COROP!$D$2:$D$41,$A2)/SUM(COROP!$Z$2:$Z$41) -> 3237.1734 | AN2: =AO2*Parameters!$B$2 -> 112.98246 | AO2: =SUMIFS(COROP!$T$2:$T$41,COROP!$D$2:$D$41,$A2)*Parameters!$F$14*(1-Parameters!$H$14)*Parameters!$G$14 -> 254.21053 | AP2: =SUMIFS(COROP!$U$2:$U$41,COROP!$D$2:$D$41,$A2)*Parameters!$F$14*(1-Parameters!$H$14)*Parameters!$G$14 -> 384.34211 | AQ2: =AR2*Parameters!$B$2 -> 149.82456 | AR2: =SUMIFS(COROP!$T$2:$T$41,COROP!$D$2:$D$41,$A2)*Parameters!$F$14*(1-Parameters!$H$14)*(1-Parameters!$G$14) -> 337.10526 | AS2: =SUMIFS(COROP!$U$2:$U$41,COROP!$D$2:$D$41,$A2)*Parameters!$F$14*(1-Parameters!$H$14)*(1-Parameters!$G$14) -> 509.67105 | AT2: =AU2*Parameters!$B$2 -> 185.38521 | AU2: =SUMIFS(COROP!$X$2:$X$41,COROP!$D$2:$D$41,$A2)*Parameters!$B$5+SUMIFS(COROP!$T$2:$T$41,COROP!$D$2:$D$41,$A2)*Parameters!$F$14*Parameters!$H$14 -> 417.11672 | AV2: =SUMIFS(COROP!$Y$2:$Y$41,COROP!$D$2:$D$41,$A2)*Parameters!$B$5+SUMIFS(COROP!$U$2:$U$41,COROP!$D$2:$D$41,$A2)*Parameters!$F$14*Parameters!$H$14 -> 480.83351 | AW2: =Parameters!$D$22*SUMIFS(COROP!$AA$2:$AA$41,COROP!$D$2:$D$41,$A2)/SUM(COROP!$AA$2:$AA$41) -> 4310 | AX2: =Parameters!$D$22*SUMIFS(COROP!$AA$2:$AA$41,COROP!$D$2:$D$41,$A2)/SUM(COROP!$AA$2:$AA$41) -> 4310 | AY2: =Parameters!$D$22*SUMIFS(COROP!$AA$2:$AA$41,COROP!$D$2:$D$41,$A2)/SUM(COROP!$AA$2:$AA$41) -> 4310
A3: 2 | B3: Friesland | C3: 3 | D3: =E3*Parameters!$B$2 -> 665.20947 | E3: =SUMIFS(COROP!$R$2:$R$41,COROP!$D$2:$D$41,$A3)*Parameters!$F$12*(1-Parameters!$H$12)*Parameters!$G$12 -> 1496.7213 | F3: =SUMIFS(COROP!$S$2:$S$41,COROP!$D$2:$D$41,$A3)*Parameters!$F$12*(1-Parameters!$H$12)*Parameters!$G$12 -> 2281.1475 | G3: =H3*Parameters!$B$2 -> 220.12386 | H3: =SUMIFS(COROP!$R$2:$R$41,COROP!$D$2:$D$41,$A3)*Parameters!$F$12*(1-Parameters!$H$12)*(1-Parameters!$G$12) -> 495.27869 | I3: =SUMIFS(COROP!$S$2:$S$41,COROP!$D$2:$D$41,$A3)*Parameters!$F$12*(1-Parameters!$H$12)*(1-Parameters!$G$12) -> 754.85246 | J3: =K3*Parameters!$B$2 -> 105.56138 | K3: =SUMIFS(COROP!$V$2:$V$41,COROP!$D$2:$D$41,$A3)*Parameters!$B$5+SUMIFS(COROP!$R$2:$R$41,COROP!$D$2:$D$41,$A3)*Parameters!$F$12*Parameters!$H$12 -> 237.5131 | L3: =SUMIFS(COROP!$W$2:$W$41,COROP!$D$2:$D$41,$A3)*Parameters!$B$5+SUMIFS(COROP!$S$2:$S$41,COROP!$D$2:$D$41,$A3)*Parameters!$F$12*Parameters!$H$12 -> 328.26114 | M3: =Parameters!$D$19*SUMIFS(COROP!$Z$2:$Z$41,COROP!$D$2:$D$41,$A3)/SUM(COROP!$Z$2:$Z$41) -> 2669.5229 | N3: =Parameters!$D$19*SUMIFS(COROP!$Z$2:$Z$41,COROP!$D$2:$D$41,$A3)/SUM(COROP!$Z$2:$Z$41) -> 2669.5229 | O3: =Parameters!$D$19*SUMIFS(COROP!$Z$2:$Z$41,COROP!$D$2:$D$41,$A3)/SUM(COROP!$Z$2:$Z$41) -> 2669.5229 | P3: =Q3*Parameters!$B$2 -> 239.00585 | Q3: =SUMIFS(COROP!$T$2:$T$41,COROP!$D$2:$D$41,$A3)*Parameters!$F$15*(1-Parameters!$H$15)*Parameters!$G$15 -> 537.76316 | R3: =SUMIFS(COROP!$U$2:$U$41,COROP!$D$2:$D$41,$A3)*Parameters!$F$15*(1-Parameters!$H$15)*Parameters!$G$15 -> 995.26316 | S3: =T3*Parameters!$B$2 -> 356.54971 | T3: =SUMIFS(COROP!$T$2:$T$41,COROP!$D$2:$D$41,$A3)*Parameters!$F$15*(1-Parameters!$H$15)*(1-Parameters!$G$15) -> 802.23684 | U3: =SUMIFS(COROP!$U$2:$U$41,COROP!$D$2:$D$41,$A3)*Parameters!$F$15*(1-Parameters!$H$15)*(1-Parameters!$G$15) -> 1484.7368 | V3: =W3*Parameters!$B$2 -> 72.094473 | W3: =SUMIFS(COROP!$X$2:$X$41,COROP!$D$2:$D$41,$A3)*Parameters!$B$5+SUMIFS(COROP!$T$2:$T$41,COROP!$D$2:$D$41,$A3)*Parameters!$F$15*Parameters!$H$15 -> 162.21256 | X3: =SUMIFS(COROP!$Y$2:$Y$41,COROP!$D$2:$D$41,$A3)*Parameters!$B$5+SUMIFS(COROP!$U$2:$U$41,COROP!$D$2:$D$41,$A3)*Parameters!$F$15*Parameters!$H$15 -> 262.72228 | Y3: =Parameters!$D$20*SUMIFS(COROP!$AA$2:$AA$41,COROP!$D$2:$D$41,$A3)/SUM(COROP!$AA$2:$AA$41) -> 2655.9865 | Z3: =Parameters!$D$20*SUMIFS(COROP!$AA$2:$AA$41,COROP!$D$2:$D$41,$A3)/SUM(COROP!$AA$2:$AA$41) -> 2655.9865 | AA3: =Parameters!$D$20*SUMIFS(COROP!$AA$2:$AA$41,COROP!$D$2:$D$41,$A3)/SUM(COROP!$AA$2:$AA$41) -> 2655.9865 | AB3: =AC3*Parameters!$B$2 -> 370.09836 | AC3: =SUMIFS(COROP!$R$2:$R$41,COROP!$D$2:$D$41,$A3)*Parameters!$F$11*(1-Parameters!$H$11)*Parameters!$G$11 -> 832.72131 | AD3: =SUMIFS(COROP!$S$2:$S$41,COROP!$D$2:$D$41,$A3)*Parameters!$F$11*(1-Parameters!$H$11)*Parameters!$G$11 -> 1269.1475 | AE3: =AF3*Parameters!$B$2 -> 147.55556 | AF3: =SUMIFS(COROP!$R$2:$R$41,COROP!$D$2:$D$41,$A3)*Parameters!$F$11*(1-Parameters!$H$11)*(1-Parameters!$G$11) -> 332 | AG3: =SUMIFS(COROP!$S$2:$S$41,COROP!$D$2:$D$41,$A3)*Parameters!$F$11*(1-Parameters!$H$11)*(1-Parameters!$G$11) -> 506 | AH3: =AI3*Parameters!$B$2 -> 144.26448 | AI3: =SUMIFS(COROP!$V$2:$V$41,COROP!$D$2:$D$41,$A3)*Parameters!$B$5+SUMIFS(COROP!$R$2:$R$41,COROP!$D$2:$D$41,$A3)*Parameters!$F$11*Parameters!$H$11 -> 324.59507 | AJ3: =SUMIFS(COROP!$W$2:$W$41,COROP!$D$2:$D$41,$A3)*Parameters!$B$5+SUMIFS(COROP!$S$2:$S$41,COROP!$D$2:$D$41,$A3)*Parameters!$F$11*Parameters!$H$11 -> 460.98245 | AK3: =Parameters!$D$21*SUMIFS(COROP!$Z$2:$Z$41,COROP!$D$2:$D$41,$A3)/SUM(COROP!$Z$2:$Z$41) -> 5415.3179 | AL3: =Parameters!$D$21*SUMIFS(COROP!$Z$2:$Z$41,COROP!$D$2:$D$41,$A3)/SUM(COROP!$Z$2:$Z$41) -> 5415.3179 | AM3: =Parameters!$D$21*SUMIFS(COROP!$Z$2:$Z$41,COROP!$D$2:$D$41,$A3)/SUM(COROP!$Z$2:$Z$41) -> 5415.3179 | AN3: =AO3*Parameters!$B$2 -> 180.23392 | AO3: =SUMIFS(COROP!$T$2:$T$41,COROP!$D$2:$D$41,$A3)*Parameters!$F$14*(1-Parameters!$H$14)*Parameters!$G$14 -> 405.52632 | AP3: =SUMIFS(COROP!$U$2:$U$41,COROP!$D$2:$D$41,$A3)*Parameters!$F$14*(1-Parameters!$H$14)*Parameters!$G$14 -> 750.52632 | AQ3: =AR3*Parameters!$B$2 -> 239.00585 | AR3: =SUMIFS(COROP!$T$2:$T$41,COROP!$D$2:$D$41,$A3)*Parameters!$F$14*(1-Parameters!$H$14)*(1-Parameters!$G$14) -> 537.76316 | AS3: =SUMIFS(COROP!$U$2:$U$41,COROP!$D$2:$D$41,$A3)*Parameters!$F$14*(1-Parameters!$H$14)*(1-Parameters!$G$14) -> 995.26316 | AT3: =AU3*Parameters!$B$2 -> 134.78453 | AU3: =SUMIFS(COROP!$X$2:$X$41,COROP!$D$2:$D$41,$A3)*Parameters!$B$5+SUMIFS(COROP!$T$2:$T$41,COROP!$D$2:$D$41,$A3)*Parameters!$F$14*Parameters!$H$14 -> 303.2652 | AV3: =SUMIFS(COROP!$Y$2:$Y$41,COROP!$D$2:$D$41,$A3)*Parameters!$B$5+SUMIFS(COROP!$U$2:$U$41,COROP!$D$2:$D$41,$A3)*Parameters!$F$14*Parameters!$H$14 -> 523.77491 | AW3: =Parameters!$D$22*SUMIFS(COROP!$AA$2:$AA$41,COROP!$D$2:$D$41,$A3)/SUM(COROP!$AA$2:$AA$41) -> 7200 | AX3: =Parameters!$D$22*SUMIFS(COROP!$AA$2:$AA$41,COROP!$D$2:$D$41,$A3)/SUM(COROP!$AA$2:$AA$41) -> 7200 | AY3: =Parameters!$D$22*SUMIFS(COROP!$AA$2:$AA$41,COROP!$D$2:$D$41,$A3)/SUM(COROP!$AA$2:$AA$41) -> 7200
A4: 3 | B4: Drenthe | C4: 3 | D4: =E4*Parameters!$B$2 -> 597.08561 | E4: =SUMIFS(COROP!$R$2:$R$41,COROP!$D$2:$D$41,$A4)*Parameters!$F$12*(1-Parameters!$H$12)*Parameters!$G$12 -> 1343.4426 | F4: =SUMIFS(COROP!$S$2:$S$41,COROP!$D$2:$D$41,$A4)*Parameters!$F$12*(1-Parameters!$H$12)*Parameters!$G$12 -> 1956.5574 | G4: =H4*Parameters!$B$2 -> 197.58106 | H4: =SUMIFS(COROP!$R$2:$R$41,COROP!$D$2:$D$41,$A4)*Parameters!$F$12*(1-Parameters!$H$12)*(1-Parameters!$G$12) -> 444.55738 | I4: =SUMIFS(COROP!$S$2:$S$41,COROP!$D$2:$D$41,$A4)*Parameters!$F$12*(1-Parameters!$H$12)*(1-Parameters!$G$12) -> 647.44262 | J4: =K4*Parameters!$B$2 -> 64.54241 | K4: =SUMIFS(COROP!$V$2:$V$41,COROP!$D$2:$D$41,$A4)*Parameters!$B$5+SUMIFS(COROP!$R$2:$R$41,COROP!$D$2:$D$41,$A4)*Parameters!$F$12*Parameters!$H$12 -> 145.22042 | L4: =SUMIFS(COROP!$W$2:$W$41,COROP!$D$2:$D$41,$A4)*Parameters!$B$5+SUMIFS(COROP!$S$2:$S$41,COROP!$D$2:$D$41,$A4)*Parameters!$F$12*Parameters!$H$12 -> 214.63391 | M4: =Parameters!$D$19*SUMIFS(COROP!$Z$2:$Z$41,COROP!$D$2:$D$41,$A4)/SUM(COROP!$Z$2:$Z$41) -> 2765.7886 | N4: =Parameters!$D$19*SUMIFS(COROP!$Z$2:$Z$41,COROP!$D$2:$D$41,$A4)/SUM(COROP!$Z$2:$Z$41) -> 2765.7886 | O4: =Parameters!$D$19*SUMIFS(COROP!$Z$2:$Z$41,COROP!$D$2:$D$41,$A4)/SUM(COROP!$Z$2:$Z$41) -> 2765.7886 | P4: =Q4*Parameters!$B$2 -> 190.84795 | Q4: =SUMIFS(COROP!$T$2:$T$41,COROP!$D$2:$D$41,$A4)*Parameters!$F$15*(1-Parameters!$H$15)*Parameters!$G$15 -> 429.40789 | R4: =SUMIFS(COROP!$U$2:$U$41,COROP!$D$2:$D$41,$A4)*Parameters!$F$15*(1-Parameters!$H$15)*Parameters!$G$15 -> 686.25 | S4: =T4*Parameters!$B$2 -> 284.7076 | T4: =SUMIFS(COROP!$T$2:$T$41,COROP!$D$2:$D$41,$A4)*Parameters!$F$15*(1-Parameters!$H$15)*(1-Parameters!$G$15) -> 640.59211 | U4: =SUMIFS(COROP!$U$2:$U$41,COROP!$D$2:$D$41,$A4)*Parameters!$F$15*(1-Parameters!$H$15)*(1-Parameters!$G$15) -> 1023.75 | V4: =W4*Parameters!$B$2 -> 46.929825 | W4: =SUMIFS(COROP!$X$2:$X$41,COROP!$D$2:$D$41,$A4)*Parameters!$B$5+SUMIFS(COROP!$T$2:$T$41,COROP!$D$2:$D$41,$A4)*Parameters!$F$15*Parameters!$H$15 -> 105.59211 | X4: =SUMIFS(COROP!$Y$2:$Y$41,COROP!$D$2:$D$41,$A4)*Parameters!$B$5+SUMIFS(COROP!$U$2:$U$41,COROP!$D$2:$D$41,$A4)*Parameters!$F$15*Parameters!$H$15 -> 168.75 | Y4: =Parameters!$D$20*SUMIFS(COROP!$AA$2:$AA$41,COROP!$D$2:$D$41,$A4)/SUM(COROP!$AA$2:$AA$41) -> 2762.9637 | Z4: =Parameters!$D$20*SUMIFS(COROP!$AA$2:$AA$41,COROP!$D$2:$D$41,$A4)/SUM(COROP!$AA$2:$AA$41) -> 2762.9637 | AA4: =Parameters!$D$20*SUMIFS(COROP!$AA$2:$AA$41,COROP!$D$2:$D$41,$A4)/SUM(COROP!$AA$2:$AA$41) -> 2762.9637 | AB4: =AC4*Parameters!$B$2 -> 332.19672 | AC4: =SUMIFS(COROP!$R$2:$R$41,COROP!$D$2:$D$41,$A4)*Parameters!$F$11*(1-Parameters!$H$11)*Parameters!$G$11 -> 747.44262 | AD4: =SUMIFS(COROP!$S$2:$S$41,COROP!$D$2:$D$41,$A4)*Parameters!$F$11*(1-Parameters!$H$11)*Parameters!$G$11 -> 1088.5574 | AE4: =AF4*Parameters!$B$2 -> 132.44444 | AF4: =SUMIFS(COROP!$R$2:$R$41,COROP!$D$2:$D$41,$A4)*Parameters!$F$11*(1-Parameters!$H$11)*(1-Parameters!$G$11) -> 298 | AG4: =SUMIFS(COROP!$S$2:$S$41,COROP!$D$2:$D$41,$A4)*Parameters!$F$11*(1-Parameters!$H$11)*(1-Parameters!$G$11) -> 434 | AH4: =AI4*Parameters!$B$2 -> 99.281937 | AI4: =SUMIFS(COROP!$V$2:$V$41,COROP!$D$2:$D$41,$A4)*Parameters!$B$5+SUMIFS(COROP!$R$2:$R$41,COROP!$D$2:$D$41,$A4)*Parameters!$F$11*Parameters!$H$11 -> 223.38436 | AJ4: =SUMIFS(COROP!$W$2:$W$41,COROP!$D$2:$D$41,$A4)*Parameters!$B$5+SUMIFS(COROP!$S$2:$S$41,COROP!$D$2:$D$41,$A4)*Parameters!$F$11*Parameters!$H$11 -> 328.46998 | AK4: =Parameters!$D$21*SUMIFS(COROP!$Z$2:$Z$41,COROP!$D$2:$D$41,$A4)/SUM(COROP!$Z$2:$Z$41) -> 5610.5998 | AL4: =Parameters!$D$21*SUMIFS(COROP!$Z$2:$Z$41,COROP!$D$2:$D$41,$A4)/SUM(COROP!$Z$2:$Z$41) -> 5610.5998 | AM4: =Parameters!$D$21*SUMIFS(COROP!$Z$2:$Z$41,COROP!$D$2:$D$41,$A4)/SUM(COROP!$Z$2:$Z$41) -> 5610.5998 | AN4: =AO4*Parameters!$B$2 -> 143.91813 | AO4: =SUMIFS(COROP!$T$2:$T$41,COROP!$D$2:$D$41,$A4)*Parameters!$F$14*(1-Parameters!$H$14)*Parameters!$G$14 -> 323.81579 | AP4: =SUMIFS(COROP!$U$2:$U$41,COROP!$D$2:$D$41,$A4)*Parameters!$F$14*(1-Parameters!$H$14)*Parameters!$G$14 -> 517.5 | AQ4: =AR4*Parameters!$B$2 -> 190.84795 | AR4: =SUMIFS(COROP!$T$2:$T$41,COROP!$D$2:$D$41,$A4)*Parameters!$F$14*(1-Parameters!$H$14)*(1-Parameters!$G$14) -> 429.40789 | AS4: =SUMIFS(COROP!$U$2:$U$41,COROP!$D$2:$D$41,$A4)*Parameters!$F$14*(1-Parameters!$H$14)*(1-Parameters!$G$14) -> 686.25 | AT4: =AU4*Parameters!$B$2 -> 96.988304 | AU4: =SUMIFS(COROP!$X$2:$X$41,COROP!$D$2:$D$41,$A4)*Parameters!$B$5+SUMIFS(COROP!$T$2:$T$41,COROP!$D$2:$D$41,$A4)*Parameters!$F$14*Parameters!$H$14 -> 218.22368 | AV4: =SUMIFS(COROP!$Y$2:$Y$41,COROP!$D$2:$D$41,$A4)*Parameters!$B$5+SUMIFS(COROP!$U$2:$U$41,COROP!$D$2:$D$41,$A4)*Parameters!$F$14*Parameters!$H$14 -> 348.75 | AW4: =Parameters!$D$22*SUMIFS(COROP!$AA$2:$AA$41,COROP!$D$2:$D$41,$A4)/SUM(COROP!$AA$2:$AA$41) -> 7490 | AX4: =Parameters!$D$22*SUMIFS(COROP!$AA$2:$AA$41,COROP!$D$2:$D$41,$A4)/SUM(COROP!$AA$2:$AA$41) -> 7490 | AY4: =Parameters!$D$22*SUMIFS(COROP!$AA$2:$AA$41,COROP!$D$2:$D$41,$A4)/SUM(COROP!$AA$2:$AA$41) -> 7490
A5: 4 | B5: Overijssel | C5: 3 | D5: =E5*Parameters!$B$2 -> 1134.0619 | E5: =SUMIFS(COROP!$R$2:$R$41,COROP!$D$2:$D$41,$A5)*Parameters!$F$12*(1-Parameters!$H$12)*Parameters!$G$12 -> 2551.6393 | F5: =SUMIFS(COROP!$S$2:$S$41,COROP!$D$2:$D$41,$A5)*Parameters!$F$12*(1-Parameters!$H$12)*Parameters!$G$12 -> 4129.5082 | G5: =H5*Parameters!$B$2 -> 375.2714 | H5: =SUMIFS(COROP!$R$2:$R$41,COROP!$D$2:$D$41,$A5)*Parameters!$F$12*(1-Parameters!$H$12)*(1-Parameters!$G$12) -> 844.36066 | I5: =SUMIFS(COROP!$S$2:$S$41,COROP!$D$2:$D$41,$A5)*Parameters!$F$12*(1-Parameters!$H$12)*(1-Parameters!$G$12) -> 1366.4918 | J5: =K5*Parameters!$B$2 -> 251.03804 | K5: =SUMIFS(COROP!$V$2:$V$41,COROP!$D$2:$D$41,$A5)*Parameters!$B$5+SUMIFS(COROP!$R$2:$R$41,COROP!$D$2:$D$41,$A5)*Parameters!$F$12*Parameters!$H$12 -> 564.83559 | L5: =SUMIFS(COROP!$W$2:$W$41,COROP!$D$2:$D$41,$A5)*Parameters!$B$5+SUMIFS(COROP!$S$2:$S$41,COROP!$D$2:$D$41,$A5)*Parameters!$F$12*Parameters!$H$12 -> 842.74579 | M5: =Parameters!$D$19*SUMIFS(COROP!$Z$2:$Z$41,COROP!$D$2:$D$41,$A5)/SUM(COROP!$Z$2:$Z$41) -> 2788.0038 | N5: =Parameters!$D$19*SUMIFS(COROP!$Z$2:$Z$41,COROP!$D$2:$D$41,$A5)/SUM(COROP!$Z$2:$Z$41) -> 2788.0038 | O5: =Parameters!$D$19*SUMIFS(COROP!$Z$2:$Z$41,COROP!$D$2:$D$41,$A5)/SUM(COROP!$Z$2:$Z$41) -> 2788.0038 | P5: =Q5*Parameters!$B$2 -> 328.18713 | Q5: =SUMIFS(COROP!$T$2:$T$41,COROP!$D$2:$D$41,$A5)*Parameters!$F$15*(1-Parameters!$H$15)*Parameters!$G$15 -> 738.42105 | R5: =SUMIFS(COROP!$U$2:$U$41,COROP!$D$2:$D$41,$A5)*Parameters!$F$15*(1-Parameters!$H$15)*Parameters!$G$15 -> 1135.7237 | S5: =T5*Parameters!$B$2 -> 489.59064 | T5: =SUMIFS(COROP!$T$2:$T$41,COROP!$D$2:$D$41,$A5)*Parameters!$F$15*(1-Parameters!$H$15)*(1-Parameters!$G$15) -> 1101.5789 | U5: =SUMIFS(COROP!$U$2:$U$41,COROP!$D$2:$D$41,$A5)*Parameters!$F$15*(1-Parameters!$H$15)*(1-Parameters!$G$15) -> 1694.2763 | V5: =W5*Parameters!$B$2 -> 136.65644 | W5: =SUMIFS(COROP!$X$2:$X$41,COROP!$D$2:$D$41,$A5)*Parameters!$B$5+SUMIFS(COROP!$T$2:$T$41,COROP!$D$2:$D$41,$A5)*Parameters!$F$15*Parameters!$H$15 -> 307.47698 | X5: =SUMIFS(COROP!$Y$2:$Y$41,COROP!$D$2:$D$41,$A5)*Parameters!$B$5+SUMIFS(COROP!$U$2:$U$41,COROP!$D$2:$D$41,$A5)*Parameters!$F$15*Parameters!$H$15 -> 435.15007 | Y5: =Parameters!$D$20*SUMIFS(COROP!$AA$2:$AA$41,COROP!$D$2:$D$41,$A5)/SUM(COROP!$AA$2:$AA$41) -> 2785.097 | Z5: =Parameters!$D$20*SUMIFS(COROP!$AA$2:$AA$41,COROP!$D$2:$D$41,$A5)/SUM(COROP!$AA$2:$AA$41) -> 2785.097 | AA5: =Parameters!$D$20*SUMIFS(COROP!$AA$2:$AA$41,COROP!$D$2:$D$41,$A5)/SUM(COROP!$AA$2:$AA$41) -> 2785.097 | AB5: =AC5*Parameters!$B$2 -> 630.95082 | AC5: =SUMIFS(COROP!$R$2:$R$41,COROP!$D$2:$D$41,$A5)*Parameters!$F$11*(1-Parameters!$H$11)*Parameters!$G$11 -> 1419.6393 | AD5: =SUMIFS(COROP!$S$2:$S$41,COROP!$D$2:$D$41,$A5)*Parameters!$F$11*(1-Parameters!$H$11)*Parameters!$G$11 -> 2297.5082 | AE5: =AF5*Parameters!$B$2 -> 251.55556 | AF5: =SUMIFS(COROP!$R$2:$R$41,COROP!$D$2:$D$41,$A5)*Parameters!$F$11*(1-Parameters!$H$11)*(1-Parameters!$G$11) -> 566 | AG5: =SUMIFS(COROP!$S$2:$S$41,COROP!$D$2:$D$41,$A5)*Parameters!$F$11*(1-Parameters!$H$11)*(1-Parameters!$G$11) -> 916 | AH5: =AI5*Parameters!$B$2 -> 317.01982 | AI5: =SUMIFS(COROP!$V$2:$V$41,COROP!$D$2:$D$41,$A5)*Parameters!$B$5+SUMIFS(COROP!$R$2:$R$41,COROP!$D$2:$D$41,$A5)*Parameters!$F$11*Parameters!$H$11 -> 713.29461 | AJ5: =SUMIFS(COROP!$W$2:$W$41,COROP!$D$2:$D$41,$A5)*Parameters!$B$5+SUMIFS(COROP!$S$2:$S$41,COROP!$D$2:$D$41,$A5)*Parameters!$F$11*Parameters!$H$11 -> 1083.0081 | AK5: =Parameters!$D$21*SUMIFS(COROP!$Z$2:$Z$41,COROP!$D$2:$D$41,$A5)/SUM(COROP!$Z$2:$Z$41) -> 5655.6649 | AL5: =Parameters!$D$21*SUMIFS(COROP!$Z$2:$Z$41,COROP!$D$2:$D$41,$A5)/SUM(COROP!$Z$2:$Z$41) -> 5655.6649 | AM5: =Parameters!$D$21*SUMIFS(COROP!$Z$2:$Z$41,COROP!$D$2:$D$41,$A5)/SUM(COROP!$Z$2:$Z$41) -> 5655.6649 | AN5: =AO5*Parameters!$B$2 -> 247.48538 | AO5: =SUMIFS(COROP!$T$2:$T$41,COROP!$D$2:$D$41,$A5)*Parameters!$F$14*(1-Parameters!$H$14)*Parameters!$G$14 -> 556.84211 | AP5: =SUMIFS(COROP!$U$2:$U$41,COROP!$D$2:$D$41,$A5)*Parameters!$F$14*(1-Parameters!$H$14)*Parameters!$G$14 -> 856.44737 | AQ5: =AR5*Parameters!$B$2 -> 328.18713 | AR5: =SUMIFS(COROP!$T$2:$T$41,COROP!$D$2:$D$41,$A5)*Parameters!$F$14*(1-Parameters!$H$14)*(1-Parameters!$G$14) -> 738.42105 | AS5: =SUMIFS(COROP!$U$2:$U$41,COROP!$D$2:$D$41,$A5)*Parameters!$F$14*(1-Parameters!$H$14)*(1-Parameters!$G$14) -> 1135.7237 | AT5: =AU5*Parameters!$B$2 -> 222.73831 | AU5: =SUMIFS(COROP!$X$2:$X$41,COROP!$D$2:$D$41,$A5)*Parameters!$B$5+SUMIFS(COROP!$T$2:$T$41,COROP!$D$2:$D$41,$A5)*Parameters!$F$14*Parameters!$H$14 -> 501.16119 | AV5: =SUMIFS(COROP!$Y$2:$Y$41,COROP!$D$2:$D$41,$A5)*Parameters!$B$5+SUMIFS(COROP!$U$2:$U$41,COROP!$D$2:$D$41,$A5)*Parameters!$F$14*Parameters!$H$14 -> 733.04481 | AW5: =Parameters!$D$22*SUMIFS(COROP!$AA$2:$AA$41,COROP!$D$2:$D$41,$A5)/SUM(COROP!$AA$2:$AA$41) -> 7550 | AX5: =Parameters!$D$22*SUMIFS(COROP!$AA$2:$AA$41,COROP!$D$2:$D$41,$A5)/SUM(COROP!$AA$2:$AA$41) -> 7550 | AY5: =Parameters!$D$22*SUMIFS(COROP!$AA$2:$AA$41,COROP!$D$2:$D$41,$A5)/SUM(COROP!$AA$2:$AA$41) -> 7550
A6: 5 | B6: Gelderland | C6: 2 | D6: =E6*Parameters!$B$2 -> 2135.8834 | E6: =SUMIFS(COROP!$R$2:$R$41,COROP!$D$2:$D$41,$A6)*Parameters!$F$12*(1-Parameters!$H$12)*Parameters!$G$12 -> 4805.7377 | F6: =SUMIFS(COROP!$S$2:$S$41,COROP!$D$2:$D$41,$A6)*Parameters!$F$12*(1-Parameters!$H$12)*Parameters!$G$12 -> 9097.541 | G6: =H6*Parameters!$B$2 -> 706.78324 | H6: =SUMIFS(COROP!$R$2:$R$41,COROP!$D$2:$D$41,$A6)*Parameters!$F$12*(1-Parameters!$H$12)*(1-Parameters!$G$12) -> 1590.2623 | I6: =SUMIFS(COROP!$S$2:$S$41,COROP!$D$2:$D$41,$A6)*Parameters!$F$12*(1-Parameters!$H$12)*(1-Parameters!$G$12) -> 3010.459 | J6: =K6*Parameters!$B$2 -> 779.96539 | K6: =SUMIFS(COROP!$V$2:$V$41,COROP!$D$2:$D$41,$A6)*Parameters!$B$5+SUMIFS(COROP!$R$2:$R$41,COROP!$D$2:$D$41,$A6)*Parameters!$F$12*Parameters!$H$12 -> 1754.9221 | L6: =SUMIFS(COROP!$W$2:$W$41,COROP!$D$2:$D$41,$A6)*Parameters!$B$5+SUMIFS(COROP!$S$2:$S$41,COROP!$D$2:$D$41,$A6)*Parameters!$F$12*Parameters!$H$12 -> 2654.4815 | M6: =Parameters!$D$19*SUMIFS(COROP!$Z$2:$Z$41,COROP!$D$2:$D$41,$A6)/SUM(COROP!$Z$2:$Z$41) -> 4502.2744 | N6: =Parameters!$D$19*SUMIFS(COROP!$Z$2:$Z$41,COROP!$D$2:$D$41,$A6)/SUM(COROP!$Z$2:$Z$41) -> 4502.2744 | O6: =Parameters!$D$19*SUMIFS(COROP!$Z$2:$Z$41,COROP!$D$2:$D$41,$A6)/SUM(COROP!$Z$2:$Z$41) -> 4502.2744 | P6: =Q6*Parameters!$B$2 -> 328.18713 | Q6: =SUMIFS(COROP!$T$2:$T$41,COROP!$D$2:$D$41,$A6)*Parameters!$F$15*(1-Parameters!$H$15)*Parameters!$G$15 -> 738.42105 | R6: =SUMIFS(COROP!$U$2:$U$41,COROP!$D$2:$D$41,$A6)*Parameters!$F$15*(1-Parameters!$H$15)*Parameters!$G$15 -> 1272.1711 | S6: =T6*Parameters!$B$2 -> 489.59064 | T6: =SUMIFS(COROP!$T$2:$T$41,COROP!$D$2:$D$41,$A6)*Parameters!$F$15*(1-Parameters!$H$15)*(1-Parameters!$G$15) -> 1101.5789 | U6: =SUMIFS(COROP!$U$2:$U$41,COROP!$D$2:$D$41,$A6)*Parameters!$F$15*(1-Parameters!$H$15)*(1-Parameters!$G$15) -> 1897.8289 | V6: =W6*Parameters!$B$2 -> 325.83655 | W6: =SUMIFS(COROP!$X$2:$X$41,COROP!$D$2:$D$41,$A6)*Parameters!$B$5+SUMIFS(COROP!$T$2:$T$41,COROP!$D$2:$D$41,$A6)*Parameters!$F$15*Parameters!$H$15 -> 733.13224 | X6: =SUMIFS(COROP!$Y$2:$Y$41,COROP!$D$2:$D$41,$A6)*Parameters!$B$5+SUMIFS(COROP!$U$2:$U$41,COROP!$D$2:$D$41,$A6)*Parameters!$F$15*Parameters!$H$15 -> 798.43565 | Y6: =Parameters!$D$20*SUMIFS(COROP!$AA$2:$AA$41,COROP!$D$2:$D$41,$A6)/SUM(COROP!$AA$2:$AA$41) -> 4518.8659 | Z6: =Parameters!$D$20*SUMIFS(COROP!$AA$2:$AA$41,COROP!$D$2:$D$41,$A6)/SUM(COROP!$AA$2:$AA$41) -> 4518.8659 | AA6: =Parameters!$D$20*SUMIFS(COROP!$AA$2:$AA$41,COROP!$D$2:$D$41,$A6)/SUM(COROP!$AA$2:$AA$41) -> 4518.8659 | AB6: =AC6*Parameters!$B$2 -> 1188.3279 | AC6: =SUMIFS(COROP!$R$2:$R$41,COROP!$D$2:$D$41,$A6)*Parameters!$F$11*(1-Parameters!$H$11)*Parameters!$G$11 -> 2673.7377 | AD6: =SUMIFS(COROP!$S$2:$S$41,COROP!$D$2:$D$41,$A6)*Parameters!$F$11*(1-Parameters!$H$11)*Parameters!$G$11 -> 5061.541 | AE6: =AF6*Parameters!$B$2 -> 473.77778 | AF6: =SUMIFS(COROP!$R$2:$R$41,COROP!$D$2:$D$41,$A6)*Parameters!$F$11*(1-Parameters!$H$11)*(1-Parameters!$G$11) -> 1066 | AG6: =SUMIFS(COROP!$S$2:$S$41,COROP!$D$2:$D$41,$A6)*Parameters!$F$11*(1-Parameters!$H$11)*(1-Parameters!$G$11) -> 2018 | AH6: =AI6*Parameters!$B$2 -> 904.23497 | AI6: =SUMIFS(COROP!$V$2:$V$41,COROP!$D$2:$D$41,$A6)*Parameters!$B$5+SUMIFS(COROP!$R$2:$R$41,COROP!$D$2:$D$41,$A6)*Parameters!$F$11*Parameters!$H$11 -> 2034.5287 | AJ6: =SUMIFS(COROP!$W$2:$W$41,COROP!$D$2:$D$41,$A6)*Parameters!$B$5+SUMIFS(COROP!$S$2:$S$41,COROP!$D$2:$D$41,$A6)*Parameters!$F$11*Parameters!$H$11 -> 3183.793 | AK6: =Parameters!$D$21*SUMIFS(COROP!$Z$2:$Z$41,COROP!$D$2:$D$41,$A6)/SUM(COROP!$Z$2:$Z$41) -> 9133.1852 | AL6: =Parameters!$D$21*SUMIFS(COROP!$Z$2:$Z$41,COROP!$D$2:$D$41,$A6)/SUM(COROP!$Z$2:$Z$41) -> 9133.1852 | AM6: =Parameters!$D$21*SUMIFS(COROP!$Z$2:$Z$41,COROP!$D$2:$D$41,$A6)/SUM(COROP!$Z$2:$Z$41) -> 9133.1852 | AN6: =AO6*Parameters!$B$2 -> 247.48538 | AO6: =SUMIFS(COROP!$T$2:$T$41,COROP!$D$2:$D$41,$A6)*Parameters!$F$14*(1-Parameters!$H$14)*Parameters!$G$14 -> 556.84211 | AP6: =SUMIFS(COROP!$U$2:$U$41,COROP!$D$2:$D$41,$A6)*Parameters!$F$14*(1-Parameters!$H$14)*Parameters!$G$14 -> 959.34211 | AQ6: =AR6*Parameters!$B$2 -> 328.18713 | AR6: =SUMIFS(COROP!$T$2:$T$41,COROP!$D$2:$D$41,$A6)*Parameters!$F$14*(1-Parameters!$H$14)*(1-Parameters!$G$14) -> 738.42105 | AS6: =SUMIFS(COROP!$U$2:$U$41,COROP!$D$2:$D$41,$A6)*Parameters!$F$14*(1-Parameters!$H$14)*(1-Parameters!$G$14) -> 1272.1711 | AT6: =AU6*Parameters!$B$2 -> 411.91842 | AU6: =SUMIFS(COROP!$X$2:$X$41,COROP!$D$2:$D$41,$A6)*Parameters!$B$5+SUMIFS(COROP!$T$2:$T$41,COROP!$D$2:$D$41,$A6)*Parameters!$F$14*Parameters!$H$14 -> 926.81645 | AV6: =SUMIFS(COROP!$Y$2:$Y$41,COROP!$D$2:$D$41,$A6)*Parameters!$B$5+SUMIFS(COROP!$U$2:$U$41,COROP!$D$2:$D$41,$A6)*Parameters!$F$14*Parameters!$H$14 -> 1132.1199 | AW6: =Parameters!$D$22*SUMIFS(COROP!$AA$2:$AA$41,COROP!$D$2:$D$41,$A6)/SUM(COROP!$AA$2:$AA$41) -> 12250 | AX6: =Parameters!$D$22*SUMIFS(COROP!$AA$2:$AA$41,COROP!$D$2:$D$41,$A6)/SUM(COROP!$AA$2:$AA$41) -> 12250 | AY6: =Parameters!$D$22*SUMIFS(COROP!$AA$2:$AA$41,COROP!$D$2:$D$41,$A6)/SUM(COROP!$AA$2:$AA$41) -> 12250
A7: 6 | B7: Utrecht | C7: 1 | D7: =E7*Parameters!$B$2 -> 1482.6958 | E7: =SUMIFS(COROP!$R$2:$R$41,COROP!$D$2:$D$41,$A7)*Parameters!$F$12*(1-Parameters!$H$12)*Parameters!$G$12 -> 3336.0656 | F7: =SUMIFS(COROP!$S$2:$S$41,COROP!$D$2:$D$41,$A7)*Parameters!$F$12*(1-Parameters!$H$12)*Parameters!$G$12 -> 6897.541 | G7: =H7*Parameters!$B$2 -> 490.63752 | H7: =SUMIFS(COROP!$R$2:$R$41,COROP!$D$2:$D$41,$A7)*Parameters!$F$12*(1-Parameters!$H$12)*(1-Parameters!$G$12) -> 1103.9344 | I7: =SUMIFS(COROP!$S$2:$S$41,COROP!$D$2:$D$41,$A7)*Parameters!$F$12*(1-Parameters!$H$12)*(1-Parameters!$G$12) -> 2282.459 | J7: =K7*Parameters!$B$2 -> 933.51709 | K7: =SUMIFS(COROP!$V$2:$V$41,COROP!$D$2:$D$41,$A7)*Parameters!$B$5+SUMIFS(COROP!$R$2:$R$41,COROP!$D$2:$D$41,$A7)*Parameters!$F$12*Parameters!$H$12 -> 2100.4135 | L7: =SUMIFS(COROP!$W$2:$W$41,COROP!$D$2:$D$41,$A7)*Parameters!$B$5+SUMIFS(COROP!$S$2:$S$41,COROP!$D$2:$D$41,$A7)*Parameters!$F$12*Parameters!$H$12 -> 3253.8989 | M7: =Parameters!$D$19*SUMIFS(COROP!$Z$2:$Z$41,COROP!$D$2:$D$41,$A7)/SUM(COROP!$Z$2:$Z$41) -> 1240.347 | N7: =Parameters!$D$19*SUMIFS(COROP!$Z$2:$Z$41,COROP!$D$2:$D$41,$A7)/SUM(COROP!$Z$2:$Z$41) -> 1240.347 | O7: =Parameters!$D$19*SUMIFS(COROP!$Z$2:$Z$41,COROP!$D$2:$D$41,$A7)/SUM(COROP!$Z$2:$Z$41) -> 1240.347 | P7: =Q7*Parameters!$B$2 -> 258.62573 | Q7: =SUMIFS(COROP!$T$2:$T$41,COROP!$D$2:$D$41,$A7)*Parameters!$F$15*(1-Parameters!$H$15)*Parameters!$G$15 -> 581.90789 | R7: =SUMIFS(COROP!$U$2:$U$41,COROP!$D$2:$D$41,$A7)*Parameters!$F$15*(1-Parameters!$H$15)*Parameters!$G$15 -> 838.75 | S7: =T7*Parameters!$B$2 -> 385.81871 | T7: =SUMIFS(COROP!$T$2:$T$41,COROP!$D$2:$D$41,$A7)*Parameters!$F$15*(1-Parameters!$H$15)*(1-Parameters!$G$15) -> 868.09211 | U7: =SUMIFS(COROP!$U$2:$U$41,COROP!$D$2:$D$41,$A7)*Parameters!$F$15*(1-Parameters!$H$15)*(1-Parameters!$G$15) -> 1251.25 | V7: =W7*Parameters!$B$2 -> 436.62771 | W7: =SUMIFS(COROP!$X$2:$X$41,COROP!$D$2:$D$41,$A7)*Parameters!$B$5+SUMIFS(COROP!$T$2:$T$41,COROP!$D$2:$D$41,$A7)*Parameters!$F$15*Parameters!$H$15 -> 982.41234 | X7: =SUMIFS(COROP!$Y$2:$Y$41,COROP!$D$2:$D$41,$A7)*Parameters!$B$5+SUMIFS(COROP!$U$2:$U$41,COROP!$D$2:$D$41,$A7)*Parameters!$F$15*Parameters!$H$15 -> 1105.5217 | Y7: =Parameters!$D$20*SUMIFS(COROP!$AA$2:$AA$41,COROP!$D$2:$D$41,$A7)/SUM(COROP!$AA$2:$AA$41) -> 1254.2159 | Z7: =Parameters!$D$20*SUMIFS(COROP!$AA$2:$AA$41,COROP!$D$2:$D$41,$A7)/SUM(COROP!$AA$2:$AA$41) -> 1254.2159 | AA7: =Parameters!$D$20*SUMIFS(COROP!$AA$2:$AA$41,COROP!$D$2:$D$41,$A7)/SUM(COROP!$AA$2:$AA$41) -> 1254.2159 | AB7: =AC7*Parameters!$B$2 -> 824.91803 | AC7: =SUMIFS(COROP!$R$2:$R$41,COROP!$D$2:$D$41,$A7)*Parameters!$F$11*(1-Parameters!$H$11)*Parameters!$G$11 -> 1856.0656 | AD7: =SUMIFS(COROP!$S$2:$S$41,COROP!$D$2:$D$41,$A7)*Parameters!$F$11*(1-Parameters!$H$11)*Parameters!$G$11 -> 3837.541 | AE7: =AF7*Parameters!$B$2 -> 328.88889 | AF7: =SUMIFS(COROP!$R$2:$R$41,COROP!$D$2:$D$41,$A7)*Parameters!$F$11*(1-Parameters!$H$11)*(1-Parameters!$G$11) -> 740 | AG7: =SUMIFS(COROP!$S$2:$S$41,COROP!$D$2:$D$41,$A7)*Parameters!$F$11*(1-Parameters!$H$11)*(1-Parameters!$G$11) -> 1530 | AH7: =AI7*Parameters!$B$2 -> 1019.783 | AI7: =SUMIFS(COROP!$V$2:$V$41,COROP!$D$2:$D$41,$A7)*Parameters!$B$5+SUMIFS(COROP!$R$2:$R$41,COROP!$D$2:$D$41,$A7)*Parameters!$F$11*Parameters!$H$11 -> 2294.5118 | AJ7: =SUMIFS(COROP!$W$2:$W$41,COROP!$D$2:$D$41,$A7)*Parameters!$B$5+SUMIFS(COROP!$S$2:$S$41,COROP!$D$2:$D$41,$A7)*Parameters!$F$11*Parameters!$H$11 -> 3655.2104 | AK7: =Parameters!$D$21*SUMIFS(COROP!$Z$2:$Z$41,COROP!$D$2:$D$41,$A7)/SUM(COROP!$Z$2:$Z$41) -> 2516.1324 | AL7: =Parameters!$D$21*SUMIFS(COROP!$Z$2:$Z$41,COROP!$D$2:$D$41,$A7)/SUM(COROP!$Z$2:$Z$41) -> 2516.1324 | AM7: =Parameters!$D$21*SUMIFS(COROP!$Z$2:$Z$41,COROP!$D$2:$D$41,$A7)/SUM(COROP!$Z$2:$Z$41) -> 2516.1324 | AN7: =AO7*Parameters!$B$2 -> 195.02924 | AO7: =SUMIFS(COROP!$T$2:$T$41,COROP!$D$2:$D$41,$A7)*Parameters!$F$14*(1-Parameters!$H$14)*Parameters!$G$14 -> 438.81579 | AP7: =SUMIFS(COROP!$U$2:$U$41,COROP!$D$2:$D$41,$A7)*Parameters!$F$14*(1-Parameters!$H$14)*Parameters!$G$14 -> 632.5 | AQ7: =AR7*Parameters!$B$2 -> 258.62573 | AR7: =SUMIFS(COROP!$T$2:$T$41,COROP!$D$2:$D$41,$A7)*Parameters!$F$14*(1-Parameters!$H$14)*(1-Parameters!$G$14) -> 581.90789 | AS7: =SUMIFS(COROP!$U$2:$U$41,COROP!$D$2:$D$41,$A7)*Parameters!$F$14*(1-Parameters!$H$14)*(1-Parameters!$G$14) -> 838.75 | AT7: =AU7*Parameters!$B$2 -> 504.46396 | AU7: =SUMIFS(COROP!$X$2:$X$41,COROP!$D$2:$D$41,$A7)*Parameters!$B$5+SUMIFS(COROP!$T$2:$T$41,COROP!$D$2:$D$41,$A7)*Parameters!$F$14*Parameters!$H$14 -> 1135.0439 | AV7: =SUMIFS(COROP!$Y$2:$Y$41,COROP!$D$2:$D$41,$A7)*Parameters!$B$5+SUMIFS(COROP!$U$2:$U$41,COROP!$D$2:$D$41,$A7)*Parameters!$F$14*Parameters!$H$14 -> 1325.5217 | AW7: =Parameters!$D$22*SUMIFS(COROP!$AA$2:$AA$41,COROP!$D$2:$D$41,$A7)/SUM(COROP!$AA$2:$AA$41) -> 3400 | AX7: =Parameters!$D$22*SUMIFS(COROP!$AA$2:$AA$41,COROP!$D$2:$D$41,$A7)/SUM(COROP!$AA$2:$AA$41) -> 3400 | AY7: =Parameters!$D$22*SUMIFS(COROP!$AA$2:$AA$41,COROP!$D$2:$D$41,$A7)/SUM(COROP!$AA$2:$AA$41) -> 3400
A8: 7 | B8: Noord-Holland | C8: 1 | D8: =E8*Parameters!$B$2 -> 2171.949 | E8: =SUMIFS(COROP!$R$2:$R$41,COROP!$D$2:$D$41,$A8)*Parameters!$F$12*(1-Parameters!$H$12)*Parameters!$G$12 -> 4886.8852 | F8: =SUMIFS(COROP!$S$2:$S$41,COROP!$D$2:$D$41,$A8)*Parameters!$F$12*(1-Parameters!$H$12)*Parameters!$G$12 -> 7880.3279 | G8: =H8*Parameters!$B$2 -> 718.71767 | H8: =SUMIFS(COROP!$R$2:$R$41,COROP!$D$2:$D$41,$A8)*Parameters!$F$12*(1-Parameters!$H$12)*(1-Parameters!$G$12) -> 1617.1148 | I8: =SUMIFS(COROP!$S$2:$S$41,COROP!$D$2:$D$41,$A8)*Parameters!$F$12*(1-Parameters!$H$12)*(1-Parameters!$G$12) -> 2607.6721 | J8: =K8*Parameters!$B$2 -> 1821.091 | K8: =SUMIFS(COROP!$V$2:$V$41,COROP!$D$2:$D$41,$A8)*Parameters!$B$5+SUMIFS(COROP!$R$2:$R$41,COROP!$D$2:$D$41,$A8)*Parameters!$F$12*Parameters!$H$12 -> 4097.4547 | L8: =SUMIFS(COROP!$W$2:$W$41,COROP!$D$2:$D$41,$A8)*Parameters!$B$5+SUMIFS(COROP!$S$2:$S$41,COROP!$D$2:$D$41,$A8)*Parameters!$F$12*Parameters!$H$12 -> 5519.7138 | M8: =Parameters!$D$19*SUMIFS(COROP!$Z$2:$Z$41,COROP!$D$2:$D$41,$A8)/SUM(COROP!$Z$2:$Z$41) -> 5361.261 | N8: =Parameters!$D$19*SUMIFS(COROP!$Z$2:$Z$41,COROP!$D$2:$D$41,$A8)/SUM(COROP!$Z$2:$Z$41) -> 5361.261 | O8: =Parameters!$D$19*SUMIFS(COROP!$Z$2:$Z$41,COROP!$D$2:$D$41,$A8)/SUM(COROP!$Z$2:$Z$41) -> 5361.261 | P8: =Q8*Parameters!$B$2 -> 424.50292 | Q8: =SUMIFS(COROP!$T$2:$T$41,COROP!$D$2:$D$41,$A8)*Parameters!$F$15*(1-Parameters!$H$15)*Parameters!$G$15 -> 955.13158 | R8: =SUMIFS(COROP!$U$2:$U$41,COROP!$D$2:$D$41,$A8)*Parameters!$F$15*(1-Parameters!$H$15)*Parameters!$G$15 -> 1392.5658 | S8: =T8*Parameters!$B$2 -> 633.27485 | T8: =SUMIFS(COROP!$T$2:$T$41,COROP!$D$2:$D$41,$A8)*Parameters!$F$15*(1-Parameters!$H$15)*(1-Parameters!$G$15) -> 1424.8684 | U8: =SUMIFS(COROP!$U$2:$U$41,COROP!$D$2:$D$41,$A8)*Parameters!$F$15*(1-Parameters!$H$15)*(1-Parameters!$G$15) -> 2077.4342 | V8: =W8*Parameters!$B$2 -> 1042.293 | W8: =SUMIFS(COROP!$X$2:$X$41,COROP!$D$2:$D$41,$A8)*Parameters!$B$5+SUMIFS(COROP!$T$2:$T$41,COROP!$D$2:$D$41,$A8)*Parameters!$F$15*Parameters!$H$15 -> 2345.1593 | X8: =SUMIFS(COROP!$Y$2:$Y$41,COROP!$D$2:$D$41,$A8)*Parameters!$B$5+SUMIFS(COROP!$U$2:$U$41,COROP!$D$2:$D$41,$A8)*Parameters!$F$15*Parameters!$H$15 -> 2662.5551 | Y8: =Parameters!$D$20*SUMIFS(COROP!$AA$2:$AA$41,COROP!$D$2:$D$41,$A8)/SUM(COROP!$AA$2:$AA$41) -> 5345.1728 | Z8: =Parameters!$D$20*SUMIFS(COROP!$AA$2:$AA$41,COROP!$D$2:$D$41,$A8)/SUM(COROP!$AA$2:$AA$41) -> 5345.1728 | AA8: =Parameters!$D$20*SUMIFS(COROP!$AA$2:$AA$41,COROP!$D$2:$D$41,$A8)/SUM(COROP!$AA$2:$AA$41) -> 5345.1728 | AB8: =AC8*Parameters!$B$2 -> 1208.3934 | AC8: =SUMIFS(COROP!$R$2:$R$41,COROP!$D$2:$D$41,$A8)*Parameters!$F$11*(1-Parameters!$H$11)*Parameters!$G$11 -> 2718.8852 | AD8: =SUMIFS(COROP!$S$2:$S$41,COROP!$D$2:$D$41,$A8)*Parameters!$F$11*(1-Parameters!$H$11)*Parameters!$G$11 -> 4384.3279 | AE8: =AF8*Parameters!$B$2 -> 481.77778 | AF8: =SUMIFS(COROP!$R$2:$R$41,COROP!$D$2:$D$41,$A8)*Parameters!$F$11*(1-Parameters!$H$11)*(1-Parameters!$G$11) -> 1084 | AG8: =SUMIFS(COROP!$S$2:$S$41,COROP!$D$2:$D$41,$A8)*Parameters!$F$11*(1-Parameters!$H$11)*(1-Parameters!$G$11) -> 1748 | AH8: =AI8*Parameters!$B$2 -> 1947.4589 | AI8: =SUMIFS(COROP!$V$2:$V$41,COROP!$D$2:$D$41,$A8)*Parameters!$B$5+SUMIFS(COROP!$R$2:$R$41,COROP!$D$2:$D$41,$A8)*Parameters!$F$11*Parameters!$H$11 -> 4381.7826 | AJ8: =SUMIFS(COROP!$W$2:$W$41,COROP!$D$2:$D$41,$A8)*Parameters!$B$5+SUMIFS(COROP!$S$2:$S$41,COROP!$D$2:$D$41,$A8)*Parameters!$F$11*Parameters!$H$11 -> 5978.2056 | AK8: =Parameters!$D$21*SUMIFS(COROP!$Z$2:$Z$41,COROP!$D$2:$D$41,$A8)/SUM(COROP!$Z$2:$Z$41) -> 10875.701 | AL8: =Parameters!$D$21*SUMIFS(COROP!$Z$2:$Z$41,COROP!$D$2:$D$41,$A8)/SUM(COROP!$Z$2:$Z$41) -> 10875.701 | AM8: =Parameters!$D$21*SUMIFS(COROP!$Z$2:$Z$41,COROP!$D$2:$D$41,$A8)/SUM(COROP!$Z$2:$Z$41) -> 10875.701 | AN8: =AO8*Parameters!$B$2 -> 320.11696 | AO8: =SUMIFS(COROP!$T$2:$T$41,COROP!$D$2:$D$41,$A8)*Parameters!$F$14*(1-Parameters!$H$14)*Parameters!$G$14 -> 720.26316 | AP8: =SUMIFS(COROP!$U$2:$U$41,COROP!$D$2:$D$41,$A8)*Parameters!$F$14*(1-Parameters!$H$14)*Parameters!$G$14 -> 1050.1316 | AQ8: =AR8*Parameters!$B$2 -> 424.50292 | AR8: =SUMIFS(COROP!$T$2:$T$41,COROP!$D$2:$D$41,$A8)*Parameters!$F$14*(1-Parameters!$H$14)*(1-Parameters!$G$14) -> 955.13158 | AS8: =SUMIFS(COROP!$U$2:$U$41,COROP!$D$2:$D$41,$A8)*Parameters!$F$14*(1-Parameters!$H$14)*(1-Parameters!$G$14) -> 1392.5658 | AT8: =AU8*Parameters!$B$2 -> 1153.638 | AU8: =SUMIFS(COROP!$X$2:$X$41,COROP!$D$2:$D$41,$A8)*Parameters!$B$5+SUMIFS(COROP!$T$2:$T$41,COROP!$D$2:$D$41,$A8)*Parameters!$F$14*Parameters!$H$14 -> 2595.6856 | AV8: =SUMIFS(COROP!$Y$2:$Y$41,COROP!$D$2:$D$41,$A8)*Parameters!$B$5+SUMIFS(COROP!$U$2:$U$41,COROP!$D$2:$D$41,$A8)*Parameters!$F$14*Parameters!$H$14 -> 3027.8183 | AW8: =Parameters!$D$22*SUMIFS(COROP!$AA$2:$AA$41,COROP!$D$2:$D$41,$A8)/SUM(COROP!$AA$2:$AA$41) -> 14490 | AX8: =Parameters!$D$22*SUMIFS(COROP!$AA$2:$AA$41,COROP!$D$2:$D$41,$A8)/SUM(COROP!$AA$2:$AA$41) -> 14490 | AY8: =Parameters!$D$22*SUMIFS(COROP!$AA$2:$AA$41,COROP!$D$2:$D$41,$A8)/SUM(COROP!$AA$2:$AA$41) -> 14490
A9: 8 | B9: Zuid-Holland | C9: 1 | D9: =E9*Parameters!$B$2 -> 3101.6393 | E9: =SUMIFS(COROP!$R$2:$R$41,COROP!$D$2:$D$41,$A9)*Parameters!$F$12*(1-Parameters!$H$12)*Parameters!$G$12 -> 6978.6885 | F9: =SUMIFS(COROP!$S$2:$S$41,COROP!$D$2:$D$41,$A9)*Parameters!$F$12*(1-Parameters!$H$12)*Parameters!$G$12 -> 13443.443 | G9: =H9*Parameters!$B$2 -> 1026.3607 | H9: =SUMIFS(COROP!$R$2:$R$41,COROP!$D$2:$D$41,$A9)*Parameters!$F$12*(1-Parameters!$H$12)*(1-Parameters!$G$12) -> 2309.3115 | I9: =SUMIFS(COROP!$S$2:$S$41,COROP!$D$2:$D$41,$A9)*Parameters!$F$12*(1-Parameters!$H$12)*(1-Parameters!$G$12) -> 4448.5574 | J9: =K9*Parameters!$B$2 -> 1917.098 | K9: =SUMIFS(COROP!$V$2:$V$41,COROP!$D$2:$D$41,$A9)*Parameters!$B$5+SUMIFS(COROP!$R$2:$R$41,COROP!$D$2:$D$41,$A9)*Parameters!$F$12*Parameters!$H$12 -> 4313.4705 | L9: =SUMIFS(COROP!$W$2:$W$41,COROP!$D$2:$D$41,$A9)*Parameters!$B$5+SUMIFS(COROP!$S$2:$S$41,COROP!$D$2:$D$41,$A9)*Parameters!$F$12*Parameters!$H$12 -> 6152.8893 | M9: =Parameters!$D$19*SUMIFS(COROP!$Z$2:$Z$41,COROP!$D$2:$D$41,$A9)/SUM(COROP!$Z$2:$Z$41) -> 3480.3766 | N9: =Parameters!$D$19*SUMIFS(COROP!$Z$2:$Z$41,COROP!$D$2:$D$41,$A9)/SUM(COROP!$Z$2:$Z$41) -> 3480.3766 | O9: =Parameters!$D$19*SUMIFS(COROP!$Z$2:$Z$41,COROP!$D$2:$D$41,$A9)/SUM(COROP!$Z$2:$Z$41) -> 3480.3766 | P9: =Q9*Parameters!$B$2 -> 583.24561 | Q9: =SUMIFS(COROP!$T$2:$T$41,COROP!$D$2:$D$41,$A9)*Parameters!$F$15*(1-Parameters!$H$15)*Parameters!$G$15 -> 1312.3026 | R9: =SUMIFS(COROP!$U$2:$U$41,COROP!$D$2:$D$41,$A9)*Parameters!$F$15*(1-Parameters!$H$15)*Parameters!$G$15 -> 2283.4868 | S9: =T9*Parameters!$B$2 -> 870.08772 | T9: =SUMIFS(COROP!$T$2:$T$41,COROP!$D$2:$D$41,$A9)*Parameters!$F$15*(1-Parameters!$H$15)*(1-Parameters!$G$15) -> 1957.6974 | U9: =SUMIFS(COROP!$U$2:$U$41,COROP!$D$2:$D$41,$A9)*Parameters!$F$15*(1-Parameters!$H$15)*(1-Parameters!$G$15) -> 3406.5132 | V9: =W9*Parameters!$B$2 -> 1060.012 | W9: =SUMIFS(COROP!$X$2:$X$41,COROP!$D$2:$D$41,$A9)*Parameters!$B$5+SUMIFS(COROP!$T$2:$T$41,COROP!$D$2:$D$41,$A9)*Parameters!$F$15*Parameters!$H$15 -> 2385.0271 | X9: =SUMIFS(COROP!$Y$2:$Y$41,COROP!$D$2:$D$41,$A9)*Parameters!$B$5+SUMIFS(COROP!$U$2:$U$41,COROP!$D$2:$D$41,$A9)*Parameters!$F$15*Parameters!$H$15 -> 2713.77 | Y9: =Parameters!$D$20*SUMIFS(COROP!$AA$2:$AA$41,COROP!$D$2:$D$41,$A9)/SUM(COROP!$AA$2:$AA$41) -> 3467.5379 | Z9: =Parameters!$D$20*SUMIFS(COROP!$AA$2:$AA$41,COROP!$D$2:$D$41,$A9)/SUM(COROP!$AA$2:$AA$41) -> 3467.5379 | AA9: =Parameters!$D$20*SUMIFS(COROP!$AA$2:$AA$41,COROP!$D$2:$D$41,$A9)/SUM(COROP!$AA$2:$AA$41) -> 3467.5379 | AB9: =AC9*Parameters!$B$2 -> 1725.6393 | AC9: =SUMIFS(COROP!$R$2:$R$41,COROP!$D$2:$D$41,$A9)*Parameters!$F$11*(1-Parameters!$H$11)*Parameters!$G$11 -> 3882.6885 | AD9: =SUMIFS(COROP!$S$2:$S$41,COROP!$D$2:$D$41,$A9)*Parameters!$F$11*(1-Parameters!$H$11)*Parameters!$G$11 -> 7479.4426 | AE9: =AF9*Parameters!$B$2 -> 688 | AF9: =SUMIFS(COROP!$R$2:$R$41,COROP!$D$2:$D$41,$A9)*Parameters!$F$11*(1-Parameters!$H$11)*(1-Parameters!$G$11) -> 1548 | AG9: =SUMIFS(COROP!$S$2:$S$41,COROP!$D$2:$D$41,$A9)*Parameters!$F$11*(1-Parameters!$H$11)*(1-Parameters!$G$11) -> 2982 | AH9: =AI9*Parameters!$B$2 -> 2097.557 | AI9: =SUMIFS(COROP!$V$2:$V$41,COROP!$D$2:$D$41,$A9)*Parameters!$B$5+SUMIFS(COROP!$R$2:$R$41,COROP!$D$2:$D$41,$A9)*Parameters!$F$11*Parameters!$H$11 -> 4719.5033 | AJ9: =SUMIFS(COROP!$W$2:$W$41,COROP!$D$2:$D$41,$A9)*Parameters!$B$5+SUMIFS(COROP!$S$2:$S$41,COROP!$D$2:$D$41,$A9)*Parameters!$F$11*Parameters!$H$11 -> 6935.0533 | AK9: =Parameters!$D$21*SUMIFS(COROP!$Z$2:$Z$41,COROP!$D$2:$D$41,$A9)/SUM(COROP!$Z$2:$Z$41) -> 7060.1925 | AL9: =Parameters!$D$21*SUMIFS(COROP!$Z$2:$Z$41,COROP!$D$2:$D$41,$A9)/SUM(COROP!$Z$2:$Z$41) -> 7060.1925 | AM9: =Parameters!$D$21*SUMIFS(COROP!$Z$2:$Z$41,COROP!$D$2:$D$41,$A9)/SUM(COROP!$Z$2:$Z$41) -> 7060.1925 | AN9: =AO9*Parameters!$B$2 -> 439.82456 | AO9: =SUMIFS(COROP!$T$2:$T$41,COROP!$D$2:$D$41,$A9)*Parameters!$F$14*(1-Parameters!$H$14)*Parameters!$G$14 -> 989.60526 | AP9: =SUMIFS(COROP!$U$2:$U$41,COROP!$D$2:$D$41,$A9)*Parameters!$F$14*(1-Parameters!$H$14)*Parameters!$G$14 -> 1721.9737 | AQ9: =AR9*Parameters!$B$2 -> 583.24561 | AR9: =SUMIFS(COROP!$T$2:$T$41,COROP!$D$2:$D$41,$A9)*Parameters!$F$14*(1-Parameters!$H$14)*(1-Parameters!$G$14) -> 1312.3026 | AS9: =SUMIFS(COROP!$U$2:$U$41,COROP!$D$2:$D$41,$A9)*Parameters!$F$14*(1-Parameters!$H$14)*(1-Parameters!$G$14) -> 2283.4868 | AT9: =AU9*Parameters!$B$2 -> 1212.9945 | AU9: =SUMIFS(COROP!$X$2:$X$41,COROP!$D$2:$D$41,$A9)*Parameters!$B$5+SUMIFS(COROP!$T$2:$T$41,COROP!$D$2:$D$41,$A9)*Parameters!$F$14*Parameters!$H$14 -> 2729.2376 | AV9: =SUMIFS(COROP!$Y$2:$Y$41,COROP!$D$2:$D$41,$A9)*Parameters!$B$5+SUMIFS(COROP!$U$2:$U$41,COROP!$D$2:$D$41,$A9)*Parameters!$F$14*Parameters!$H$14 -> 3312.7174 | AW9: =Parameters!$D$22*SUMIFS(COROP!$AA$2:$AA$41,COROP!$D$2:$D$41,$A9)/SUM(COROP!$AA$2:$AA$41) -> 9400 | AX9: =Parameters!$D$22*SUMIFS(COROP!$AA$2:$AA$41,COROP!$D$2:$D$41,$A9)/SUM(COROP!$AA$2:$AA$41) -> 9400 | AY9: =Parameters!$D$22*SUMIFS(COROP!$AA$2:$AA$41,COROP!$D$2:$D$41,$A9)/SUM(COROP!$AA$2:$AA$41) -> 9400
